Workbook

Sheet Class Log
A1: TRAINER CLASS & TRAINING LOG
A3: Trainer Name | B3: Anjali A | D3: Course | E3: FULL STACK DEV | G3: Student Name | H3: VARSHA , Sindhu , vinay | I3: DAYS - TUE, THUR , SAT | J3: Training Period | K3: 3 MONTHS
A5: S.No | B5: Student Name | C5: Date | D5: Day | E5: Start Time | F5: End Time | G5: Duration | H5: Topics Taught | I5: Task / Assignment Given | J5: Class Status | K5: Remarks
A6: 1 | B6: VARSHA | C6: 46239 | D6: =IF(C6="","",TEXT(C6,"dddd")) -> Wednesday | E6: 6.30PM | F6: 8.00PM | G6: 1.30 hours | H6: Introduce to syllabus | I6: NA | J6: Completed
A7: 2 | C7: 46242 | D7: =IF(C7="","",TEXT(C7,"dddd")) -> Saturday | E7: 6.00PM | F7: 8.00PM | G7: 2 hours | H7: what is htlm, basic structure, tags, list tag, forms,tables | I7: create a student portal - basic html page | J7: Completed | K7: here i took 2 sessions
A8: 3 | C8: 46245 | D8: =IF(C8="","",TEXT(C8,"dddd")) -> Tuesday | E8: 6.30PM | F8: 8.00PM | G8: 1.30hours | H8: Intro css , css types , selectors , different classes , units , flex, grid | I8: create a form | J8: Completed
A9: 4 | C9: 46254 | D9: =IF(C9="","",TEXT(C9,"dddd")) -> Thursday | E9: 6.30PM | F9: 8.00PM | G9: 1.30hours | H9: Bootstap, breaking points , typesof colums , covered bootstrap documentations , media queries , fluid container | I9: revise and cover all topics from bootstap doc | J9: Completed
A10: 5 | C10: 46256 | D10: =IF(C10="","",TEXT(C10,"dddd")) -> Saturday | E10: 6.30PM | F10: 8.00PM | G10: 1.30hours | H10: Javascript intro , datatypes, variable , array methods, string methods | I10: Task / Assignment Given to solve problems using array , string methods | J10: Completed
A11: 6 | C11: 46259 | D11: =IF(C11="","",TEXT(C11,"dddd")) -> Tuesday | E11: 6.30PM | F11: 8.00PM | G11: 1.30hours | H11: control flow - condition ,loops , if statements , operators | I11: Task given to solve logical problems | J11: Completed
A12: 7 | C12: 46261 | D12: =IF(C12="","",TEXT(C12,"dddd")) -> Thursday | E12: 6.30PM | F12: 8.00PM | G12: 1.30hours | H12: loops , dtw btw == , === , functions | I12: Task given to solve logical problems
A13: 8 | C13: 46263 | D13: =IF(C13="","",TEXT(C13,"dddd")) -> Saturday | E13: 5.00PM | F13: 8.00PM | G13: 3hours | H13: array method problems , object methods , different functions | I13: Javascirpt interview qus to solve - logical , method , functions | J13: Completed
A14: 9 | C14: 46268 | D14: =IF(C14="","",TEXT(C14,"dddd")) -> Thursday | E14: 6.00PM | F14: 8.00PM | G14: 2hours | H14: took review of studuent , function , rest and spread operator, promise and its methods | I14: Task given to revise all the topics , concepts , problems to solve | J14: Completed
A15: 10 | C15: 46270 | D15: =IF(C15="","",TEXT(C15,"dddd")) -> Saturday | E15: 3.30PM | F15: 8.00PM | G15: 4.30hours | H15: Call apply bind , dom and dom manipluation , | I15: Task given to create a calculator using dom and 30+ qus to solve | J15: Completed
A16: 11 | C16: 46273 | D16: =IF(C16="","",TEXT(C16,"dddd")) -> Tuesday | E16: 6.20PM | F16: 8.00PM | G16: 2.20hours | H16: diff btw libary and framework , intro react , rendering , redirecting , installation and setup steps , what is react , node.js, jsx, diff btw static and dynamic , babel compilation , components and its types , diff btw import and export in react , types of exports | I16: Task to create a expense tracker dashboard | K16: task is incomplete which i have gave in last session 5th of sept , to solve qus
A17: 12 | C17: 46275 | D17: =IF(C17="","",TEXT(C17,"dddd")) -> Thursday | E17: 6.30PM | F17: 8.00PM | G17: 1.30hours | H17: took the review , installation of react , node, npm , and setup the react to do pratical problems, package-lock.json, packjson.json , how to use the components in the file project , difft btw App.jsx , main.jsx | I17: Task given to create multiple compoenets | J17: Needs Revision | K17: Task is incomplete which gave in last session - expense tracker dashbaord, student need to revise the topics
A18: 13 | C18: 46277 | D18: =IF(C18="","",TEXT(C18,"dddd")) -> Saturday | E18: 5.00PM | F18: 7.00PM | G18: 2.00hours | H18: merits and demerits of react , rules of jsx, event handling , forms , diff btw div and fragments , create components , multiple compoenets , list and keys , props:parent to child and child to parent , CSR , SSR , state | I18: Task given to solve problems based on compoenents , props, state, lists and keys , csr and ssr | J18: Completed | K18: still task is incompleted given on 8th sept -- expense tracker dashbaord
A19: 15 | C19: 46287 | D19: =IF(C19="","",TEXT(C19,"dddd")) -> Tuesday | E19: 6.30pm | F19: 8.00pm | G19: =IF(OR(E19="",F19=""),"",F19-E19) -> #VALUE! | H19: real dom vs virtual dom , reconcillation , react hooks , usestatehook , useeffect hook | I19: task gievn to solve the hooks related problems solving
A20: 16 | D20: =IF(C20="","",TEXT(C20,"dddd")) | G20: =IF(OR(E20="",F20=""),"",F20-E20)
A21: 17 | D21: =IF(C21="","",TEXT(C21,"dddd")) | G21: =IF(OR(E21="",F21=""),"",F21-E21)
A22: 18 | D22: =IF(C22="","",TEXT(C22,"dddd")) | G22: =IF(OR(E22="",F22=""),"",F22-E22)
A23: 19 | D23: =IF(C23="","",TEXT(C23,"dddd")) | G23: =IF(OR(E23="",F23=""),"",F23-E23)
A24: 20 | D24: =IF(C24="","",TEXT(C24,"dddd")) | G24: =IF(OR(E24="",F24=""),"",F24-E24)
A25: 21 | D25: =IF(C25="","",TEXT(C25,"dddd")) | G25: =IF(OR(E25="",F25=""),"",F25-E25)
A26: 22 | D26: =IF(C26="","",TEXT(C26,"dddd")) | G26: =IF(OR(E26="",F26=""),"",F26-E26)
A27: 23 | D27: =IF(C27="","",TEXT(C27,"dddd")) | G27: =IF(OR(E27="",F27=""),"",F27-E27)
A28: 24 | D28: =IF(C28="","",TEXT(C28,"dddd")) | G28: =IF(OR(E28="",F28=""),"",F28-E28)
A29: 25 | D29: =IF(C29="","",TEXT(C29,"dddd")) | G29: =IF(OR(E29="",F29=""),"",F29-E29)
A43: S.No | B43: Student Name | C43: Date | D43: Day | E43: Start Time | F43: End Time | G43: Duration | H43: Topics Taught | I43: Task / Assignment Given | J43: Class Status | K43: Remarks
A44: 14 | B44: vinya | C44: 46274 | D44: =IF(C44="","",TEXT(C44,"dddd")) -> Wednesday | E44: 6.30PM | F44: 8.00PM | G44: 1.3 | H44: intro html , common tags - h, p , a , tables , list-ordered and unordered, alt ,different text formates | J44: Completed | K44: https://tldv.io/app/meetings/6aa15c9d449b9f0013eb082b
C45: 16-sept-2026 | E45: 6.30pm | F45: 8.00pm | H45: intro to cloud computing
C46: 18-sept-2026 | E46: 6.30pm | F46: 8.00pm | H46: cloud computing fundamentals , what , why , key benefits and characteristics , compariosn , resilience concepts
C47: 21-sept-2026 | H47: cloud service models - iass , paas , saas , shared resposibility model
A90: S.No | B90: Student Name | C90: Date | D90: Day | E90: Start Time | F90: End Time | G90: Duration | H90: Topics Taught | I90: Task / Assignment Given | J90: Class Status | K90: Remarks
A91: 1 | B91: Sindhu | C91: 46244 | E91: 6.30pm | F91: 8.00pm | G91: 1.30Hours | H91: Introduce to syllabus
A92: 2 | C92: 46252 | H92: what is htlm, basic structure, tags, list tag, forms,tables
A93: 3 | C93: 46253 | H93: Intro css , css types , selectors , different classes , units , flex, grid
A94: 4 | C94: 46255 | H94: Bootstap, breaking points , typesof colums , covered bootstrap documentations , media queries , fluid container
A95: 5 | C95: 46258
A96: 6 | C96: 46261
A97: 7 | C97: 46263
...

Sheet Summary
A1: TRAINER SUMMARY
A3: Metric | B3: Value
A4: Total Classes | B4: =COUNTA('Class Log'!C6:C999) -> 36
A5: Total Training Hours | B5: =SUM('Class Log'!G6:G999) -> #VALUE!
A6: Completed Classes | B6: =COUNTIF('Class Log'!J6:J999,"Completed") -> 11
A7: Classes In Progress | B7: =COUNTIF('Class Log'!J6:J999,"In Progress") -> 0
A8: Needs Revision | B8: =COUNTIF('Class Log'!J6:J999,"Needs Revision") -> 1
A9: Absent | B9: =COUNTIF('Class Log'!J6:J999,"Absent") -> 0

Sheet Instructions
A1: How to use this template
A2: 1 | B2: Enter trainer, course, student and training period in the top section.
A3: 2 | B3: Add one row for every class/session.
A4: 3 | B4: Enter Date, Start Time and End Time. Day and Duration calculate automatically.
A5: 4 | B5: Record the topics actually taught in Topics Taught.
A6: 5 | B6: Record homework/practical work in Task / Assignment Given.
A7: 6 | B7: Select the class status from the dropdown.
A8: 7 | B8: Use Remarks for student understanding, weaknesses, follow-up, or trainer notes.
A9: 8 | B9: Use the Summary tab for a quick overview of total classes and training hours.
